Workbook

Sheet Overview_Strategies
A1: BÁO CÁO KẾT QUẢ DIGITAL SAT BLUEBOOK
A2: Đề thi | B2: Digital SAT Practice Test — October 2026 (INT-B)
A3: Học sinh | B3: Học sinh
A4: Email học sinh | B4: Chưa cung cấp
A5: Mục tiêu điểm | B5: 1400+
A6: Thời gian nộp | B6: ---
A7: Giáo viên phụ trách | B7: Mike Pham Bá Hong Son (Google for Education Innovator: https://edudirectory.withgoogle.com/profiles/5087615831769088) - mikepham358@gmail.com
A8: Nguồn tài liệu | B8: Tham khảo từ hocsat.com
A10: BẢNG TỔNG KẾT ĐIỂM SỐ
A11: Tổng số câu | B11: =Performance_Summary!D9
A12: Số câu đã làm | B12: =Performance_Summary!E9
A13: Số câu đúng Lần 1 (100%) | B13: =Performance_Summary!F9
A14: Số câu đúng Lần 2 (66.7%) | B14: =COUNTIF(RW_Module1!M5:M31, "✅ Đúng ở L2") + COUNTIF(RW_Module2!M5:M31, "✅ Đúng ở L2") + COUNTIF(Math_Module1!M5:M26, "✅ Đúng ở L2") + COUNTIF(Math_Module2!M5:M26, "✅ Đúng ở L2")
A15: Số câu đúng Lần 3 (33.3%) | B15: =COUNTIF(RW_Module1!M5:M31, "✅ Đúng ở L3") + COUNTIF(RW_Module2!M5:M31, "✅ Đúng ở L3") + COUNTIF(Math_Module1!M5:M26, "✅ Đúng ở L3") + COUNTIF(Math_Module2!M5:M26, "✅ Đúng ở L3")
A16: Hiệu suất điểm | B16: =Performance_Summary!K9
A17: Điểm ước tính | B17: =ROUND(400 + Performance_Summary!K9 * 1200, 0) & " / 1600"
A18: Số lần thử sai ghi sổ | B18: =COUNTA(SAT_Error_Log_Tracker!A2:A100)

Sheet Performance_Summary
A1: BẢNG TỔNG HỢP KẾT QUẢ VÀ THEO DÕI TIẾN ĐỘ (OCTOBER 2026 TEST)
A2: Tự động cập nhật số câu đã làm, số lần đúng ngay Lần 1, đếm số cột sai và điểm hiệu suất (%) theo thời gian thực
A4: STT | B4: Tên Module / Phân vùng | C4: Tên Tab trong Excel | D4: Tổng số câu | E4: Đã làm Lần 1 | F4: Đúng ngay L1 | G4: Đúng ở L2/L3 | H4: Tổng số cột Sai | I4: Chưa đúng | J4: Tỷ lệ Đúng L1 (%) | K4: Điểm Hiệu suất TB (%)
A5: 1 | B5: Reading & Writing Module 1 | C5: RW_Module1 | D5: =COUNTA(RW_Module1!A5:A31) | E5: =COUNTIF(RW_Module1!F5:F31, "<>") | F5: =COUNTIF(RW_Module1!G5:G31, "✅ Đúng") | G5: =COUNTIF(RW_Module1!M5:M31, "✅ Đúng ở L2") + COUNTIF(RW_Module1!M5:M31, "✅ Đúng ở L3") | H5: =SUM(RW_Module1!L5:L31) | I5: =D5 - F5 - G5 | J5: =IF(E5>0, F5/E5, 0) | K5: =IF(D5>0, AVERAGE(RW_Module1!N5:N31), 0)
A6: 2 | B6: Reading & Writing Module 2 | C6: RW_Module2 | D6: =COUNTA(RW_Module2!A5:A31) | E6: =COUNTIF(RW_Module2!F5:F31, "<>") | F6: =COUNTIF(RW_Module2!G5:G31, "✅ Đúng") | G6: =COUNTIF(RW_Module2!M5:M31, "✅ Đúng ở L2") + COUNTIF(RW_Module2!M5:M31, "✅ Đúng ở L3") | H6: =SUM(RW_Module2!L5:L31) | I6: =D6 - F6 - G6 | J6: =IF(E6>0, F6/E6, 0) | K6: =IF(D6>0, AVERAGE(RW_Module2!N5:N31), 0)
A7: 3 | B7: Math Module 1 | C7: Math_Module1 | D7: =COUNTA(Math_Module1!A5:A26) | E7: =COUNTIF(Math_Module1!F5:F26, "<>") | F7: =COUNTIF(Math_Module1!G5:G26, "✅ Đúng") | G7: =COUNTIF(Math_Module1!M5:M26, "✅ Đúng ở L2") + COUNTIF(Math_Module1!M5:M26, "✅ Đúng ở L3") | H7: =SUM(Math_Module1!L5:L26) | I7: =D7 - F7 - G7 | J7: =IF(E7>0, F7/E7, 0) | K7: =IF(D7>0, AVERAGE(Math_Module1!N5:N26), 0)
A8: 4 | B8: Math Module 2 | C8: Math_Module2 | D8: =COUNTA(Math_Module2!A5:A26) | E8: =COUNTIF(Math_Module2!F5:F26, "<>") | F8: =COUNTIF(Math_Module2!G5:G26, "✅ Đúng") | G8: =COUNTIF(Math_Module2!M5:M26, "✅ Đúng ở L2") + COUNTIF(Math_Module2!M5:M26, "✅ Đúng ở L3") | H8: =SUM(Math_Module2!L5:L26) | I8: =D8 - F8 - G8 | J8: =IF(E8>0, F8/E8, 0) | K8: =IF(D8>0, AVERAGE(Math_Module2!N5:N26), 0)
B9: TỔNG CỘNG TOÀN BỘ ĐỀ THI | C9: --- | D9: =SUM(D5:D8) | E9: =SUM(E5:E8) | F9: =SUM(F5:F8) | G9: =SUM(G5:G8) | H9: =SUM(H5:H8) | I9: =SUM(I5:I8) | J9: =IF(E9>0, F9/E9, 0) | K9: =IF(D9>0, AVERAGE(K5:K8), 0)

Sheet SAT_Error_Log_Tracker
A1: STT | B1: Mã câu | C1: Module | D1: Chủ đề / Kỹ năng | E1: Nhóm bẫy SAT | F1: Phân tích nguyên nhân & Bài học | G1: Ghi chú tư duy | H1: Từ mới / Thuật ngữ | I1: Tình trạng | J1: Thời gian

Sheet RW_Module1
A1: Digital SAT Practice Test - October 2026: Reading & Writing Module 1
A2: Chiến thuật: Tự thử sức ở Lần 1 (Cột F) -> Nhận phản hồi tự động & Gợi ý định hướng logic mà không làm lộ đáp án.
A4: Q# | B4: Topic / Skill Focus | C4: Passage & Context | D4: Question Prompt / Calculator | E4: Options / Choices (No Answer) | F4: Lần thử 1 | G4: Kết quả L1 | H4: Lần thử 2 | I4: Kết quả L2 | J4: Lần thử 3 | K4: Kết quả L3 | L4: Tổng số cột Sai | M4: Trạng thái Hoàn thành | N4: Hiệu suất (%) | O4: Hint / Gợi ý Đa tầng (Không đáp án) | P4: Strategic Tip / Formula
A5: Q1 | B5: Vocabulary in Context (Precision) | C5: ______ the source of a malfunction in a complex electrical system can be a painstaking, time-consuming process: a repair technician may need to test each individual component one by one until the specific part causing the problematic behavior is identified. | D5: Which choice completes the text with the most logical and precise word or phrase? | E5: A. Lựa chọn A B. Lựa chọn B C. Lựa chọn C D. Lựa chọn D | G5: =IF(ISBLANK(F5), "⏳ Chờ đáp án", IF(UPPER(TRIM(F5))="B", "✅ Đúng", "❌ Sai")) | I5: =IF(ISBLANK(H5), "", IF(UPPER(TRIM(H5))="B", "✅ Đúng", "❌ Sai")) | K5: =IF(ISBLANK(J5), "", IF(UPPER(TRIM(J5))="B", "✅ Đúng", "❌ Sai")) | L5: =COUNTIF(G5, "❌ Sai") + COUNTIF(I5, "❌ Sai") + COUNTIF(K5, "❌ Sai") | M5: =IF(ISBLANK(F5), "⏳ Chờ làm", IF(G5="✅ Đúng", "✅ Đúng ngay L1", IF(I5="✅ Đúng", "✅ Đúng ở L2", IF(K5="✅ Đúng", "✅ Đúng ở L3", "❌ Chưa đúng sau 3 lần")))) | N5: =IF(G5="✅ Đúng", 1, IF(I5="✅ Đúng", 0.667, IF(K5="✅ Đúng", 0.333, 0))) | O5: =IF(ISBLANK(F5), "💡 Nhập đáp án vào Lần thử 1", IF(OR(G5="✅ Đúng", I5="✅ Đúng", K5="✅ Đúng"), "✨ Xuất sắc! Bạn đã làm đúng.", IF(NOT(ISBLANK(J5)), "💡 Gợi ý Tầng 3 (Chốt phương pháp): " & "Loại trừ các từ mang nghĩa tạo mới hay điều chỉnh chung; chọn động từ chỉ việc cô lập/xác định nguyên nhân đơn lẻ.", IF(NOT(ISBLANK(H5)), "💡 Gợi ý Tầng 2 (Manh mối cấu trúc & Loại trừ): " & "Chú ý cụm từ 'test each individual component one by one' thể hiện việc khoanh vùng chính xác bộ phận lỗi.", "💡 Gợi ý Tầng 1 (Định hướng bối cảnh): " & "Xác định vai trò của động từ cần điền trong bối cảnh kỹ thuật sửa chữa hệ thống điện.")))) | P5: =IF(OR(G5="✅ Đúng", I5="✅ Đúng", K5="✅ Đúng"), "Isolating = identifying/singling out the specific cause of a problem.", "🔒 Trả lời đúng để mở khóa Strategic Tip!")
A6: Q2 | B6: Vocabulary in Context (Biological Processes) | C6: Single-celled foraminifera inhabiting coastal waters experience significant environmental salinity changes during tidal cycles. How, then, do they ______ internal salt levels? Some organisms maintain high concentrations of phosphates that allow them to affect the concentration of internal electrolytes— including salt—in response to external changes. It may be that coastal foraminifera do the same. | D6: Which choice completes the text with the most logical and precise word or phrase? | E6: A. Lựa chọn A B. Lựa chọn B C. Lựa chọn C D. Lựa chọn D | G6: =IF(ISBLANK(F6), "⏳ Chờ đáp án", IF(UPPER(TRIM(F6))="D", "✅ Đúng", "❌ Sai")) | I6: =IF(ISBLANK(H6), "", IF(UPPER(TRIM(H6))="D", "✅ Đúng", "❌ Sai")) | K6: =IF(ISBLANK(J6), "", IF(UPPER(TRIM(J6))="D", "✅ Đúng", "❌ Sai")) | L6: =COUNTIF(G6, "❌ Sai") + COUNTIF(I6, "❌ Sai") + COUNTIF(K6, "❌ Sai") | M6: =IF(ISBLANK(F6), "⏳ Chờ làm", IF(G6="✅ Đúng", "✅ Đúng ngay L1", IF(I6="✅ Đúng", "✅ Đúng ở L2", IF(K6="✅ Đúng", "✅ Đúng ở L3", "❌ Chưa đúng sau 3 lần")))) | N6: =IF(G6="✅ Đúng", 1, IF(I6="✅ Đúng", 0.667, IF(K6="✅ Đúng", 0.333, 0))) | O6: =IF(ISBLANK(F6), "💡 Nhập đáp án vào Lần thử 1", IF(OR(G6="✅ Đúng", I6="✅ Đúng", K6="✅ Đúng"), "✨ Xuất sắc! Bạn đã làm đúng.", IF(NOT(ISBLANK(J6)), "💡 Gợi ý Tầng 3 (Chốt phương pháp): " & "Loại bỏ các động từ mang nghĩa phá hủy hay làm xáo trộn; tìm từ chỉ sự điều hòa/kiểm soát sinh học.", IF(NOT(ISBLANK(H6)), "💡 Gợi ý Tầng 2 (Manh mối cấu trúc & Loại trừ): " & "Cần một động từ miêu tả việc kiểm soát và duy trì mức độ ổn định của nồng độ muối.", "💡 Gợi ý Tầng 1 (Định hướng bối cảnh): " & "Phân tích cơ chế sinh học điều chỉnh độ mặn nội bào của loài cá ngừ được miêu tả.")))) | P6: =IF(OR(G6="✅ Đúng", I6="✅ Đúng", K6="✅ Đúng"), "Regulate = control or maintain at a steady level.", "🔒 Trả lời đúng để mở khóa Strategic Tip!")
A7: Q3 | B7: Vocabulary in Context (Research Approaches) | C7: Though most studies of the effect of altitude on blood chemistry usually concentrate on people who live above sea level, researchers Suleiman A. Al-Sweedan and Moath Alhaj have instead chosen the ______ path in their recent work of studying the blood of people who live below sea level, in locations such as the California towns of Westmorland and Thermal. | D7: Which choice completes the text with the most logical and precise word or phrase? | E7: A. Lựa chọn A B. Lựa chọn B C. Lựa chọn C D. Lựa chọn D | G7: =IF(ISBLANK(F7), "⏳ Chờ đáp án", IF(UPPER(TRIM(F7))="B", "✅ Đúng", "❌ Sai")) | I7: =IF(ISBLANK(H7), "", IF(UPPER(TRIM(H7))="B", "✅ Đúng", "❌ Sai")) | K7: =IF(ISBLANK(J7), "", IF(UPPER(TRIM(J7))="B", "✅ Đúng", "❌ Sai")) | L7: =COUNTIF(G7, "❌ Sai") + COUNTIF(I7, "❌ Sai") + COUNTIF(K7, "❌ Sai") | M7: =IF(ISBLANK(F7), "⏳ Chờ làm", IF(G7="✅ Đúng", "✅ Đúng ngay L1", IF(I7="✅ Đúng", "✅ Đúng ở L2", IF(K7="✅ Đúng", "✅ Đúng ở L3", "❌ Chưa đúng sau 3 lần")))) | N7: =IF(G7="✅ Đúng", 1, IF(I7="✅ Đúng", 0.667, IF(K7="✅ Đúng", 0.333, 0))) | O7: =IF(ISBLANK(F7), "💡 Nhập đáp án vào Lần thử 1", IF(OR(G7="✅ Đúng", I7="✅ Đúng", K7="✅ Đúng"), "✨ Xuất sắc! Bạn đã làm đúng.", IF(NOT(ISBLANK(J7)), "💡 Gợi ý Tầng 3 (Chốt phương pháp): " & "Cần từ miêu tả phương pháp làm việc khác biệt, đi ngược hoặc khác với lối tư duy truyền thống.", IF(NOT(ISBLANK(H7)), "💡 Gợi ý Tầng 2 (Manh mối cấu trúc & Loại trừ): " & "Chú ý từ nối hoặc ngữ cảnh đối lập giữa việc nghiên cứu trên đất liền và độ sâu dưới mực nước biển.", "💡 Gợi ý Tầng 1 (Định hướng bối cảnh): " & "Phân tích hướng tiếp cận nghiên cứu của nhóm tác giả đối với môi trường đại dương.")))) | P7: =IF(OR(G7="✅ Đúng", I7="✅ Đúng", K7="✅ Đúng"), "Innovative = introducing new, original, or unusual methods.", "🔒 Trả lời đúng để mở khóa Strategic Tip!")
A8: Q4 | B8: Vocabulary in Context (Sufficiency) | C8: While once ______, basic computer security training that only teaches recognition of obvious scams cannot provide enough protection against today’s sophisticated fake emails, which employ such subtle deception techniques that many organizations now require their staff to complete comprehensive cybersecurity education programs. | D8: Which choice completes the text with the most logical and precise word or phrase? | E8: A. Lựa chọn A B. Lựa chọn B C. Lựa chọn C D. Lựa chọn D | G8: =IF(ISBLANK(F8), "⏳ Chờ đáp án", IF(UPPER(TRIM(F8))="C", "✅ Đúng", "❌ Sai")) | I8: =IF(ISBLANK(H8), "", IF(UPPER(TRIM(H8))="C", "✅ Đúng", "❌ Sai")) | K8: =IF(ISBLANK(J8), "", IF(UPPER(TRIM(J8))="C", "✅ Đúng", "❌ Sai")) | L8: =COUNTIF(G8, "❌ Sai") + COUNTIF(I8, "❌ Sai") + COUNTIF(K8, "❌ Sai") | M8: =IF(ISBLANK(F8), "⏳ Chờ làm", IF(G8="✅ Đúng", "✅ Đúng ngay L1", IF(I8="✅ Đúng", "✅ Đúng ở L2", IF(K8="✅ Đúng", "✅ Đúng ở L3", "❌ Chưa đúng sau 3 lần")))) | N8: =IF(G8="✅ Đúng", 1, IF(I8="✅ Đúng", 0.667, IF(K8="✅ Đúng", 0.333, 0))) | O8: =IF(ISBLANK(F8), "💡 Nhập đáp án vào Lần thử 1", IF(OR(G8="✅ Đúng", I8="✅ Đúng", K8="✅ Đúng"), "✨ Xuất sắc! Bạn đã làm đúng.", IF(NOT(ISBLANK(J8)), "💡 Gợi ý Tầng 3 (Chốt phương pháp): " & "Chọn từ miêu tả sự đầy đủ/thỏa đáng; loại các từ mang nghĩa thái quá hoặc không đủ.", IF(NOT(ISBLANK(H8)), "💡 Gợi ý Tầng 2 (Manh mối cấu trúc & Loại trừ): " & "Chú ý vế đối lập phía sau về các đòn tấn công tinh vi đòi hỏi cấp độ bảo vệ cao hơn.", "💡 Gợi ý Tầng 1 (Định hướng bối cảnh): " & "Đọc kỹ câu văn để xác định mức độ hoặc giới hạn bảo vệ của việc đào tạo cơ bản.")))) | P8: =IF(OR(G8="✅ Đúng", I8="✅ Đúng", K8="✅ Đúng"), "Sufficient = adequate or enough for a specific requirement.", "🔒 Trả lời đúng để mở khóa Strategic Tip!")
A9: Q5 | B9: Text Structure & Overall Purpose | C9: What is a city? The answer depends on where you live! Many countries define an area as a city based on how many people live there. However, not every country uses the same numbers. Iceland defines a city as an area with a population of at least 200, while the Netherlands defines a city as having a minimum population of 20,000. Some countries even define cities using other factors, like if there is a local government. | D9: Which choice best describes the overall structure of the text? | E9: A. Lựa chọn A B. Lựa chọn B C. Lựa chọn C D. Lựa chọn D | G9: =IF(ISBLANK(F9), "⏳ Chờ đáp án", IF(UPPER(TRIM(F9))="B", "✅ Đúng", "❌ Sai")) | I9: =IF(ISBLANK(H9), "", IF(UPPER(TRIM(H9))="B", "✅ Đúng", "❌ Sai")) | K9: =IF(ISBLANK(J9), "", IF(UPPER(TRIM(J9))="B", "✅ Đúng", "❌ Sai")) | L9: =COUNTIF(G9, "❌ Sai") + COUNTIF(I9, "❌ Sai") + COUNTIF(K9, "❌ Sai") | M9: =IF(ISBLANK(F9), "⏳ Chờ làm", IF(G9="✅ Đúng", "✅ Đúng ngay L1", IF(I9="✅ Đúng", "✅ Đúng ở L2", IF(K9="✅ Đúng", "✅ Đúng ở L3", "❌ Chưa đúng sau 3 lần")))) | N9: =IF(G9="✅ Đúng", 1, IF(I9="✅ Đúng", 0.667, IF(K9="✅ Đúng", 0.333, 0))) | O9: =IF(ISBLANK(F9), "💡 Nhập đáp án vào Lần thử 1", IF(OR(G9="✅ Đúng", I9="✅ Đúng", K9="✅ Đúng"), "✨ Xuất sắc! Bạn đã làm đúng.", IF(NOT(ISBLANK(J9)), "💡 Gợi ý Tầng 3 (Chốt phương pháp): " & "Mục đích chính là trình bày các quan điểm đa dạng về một khái niệm thay vì chỉ bảo vệ một góc nhìn duy nhất.", IF(NOT(ISBLANK(H9)), "💡 Gợi ý Tầng 2 (Manh mối cấu trúc & Loại trừ): " & "Bài đọc bắt đầu bằng câu hỏi 'What is a city?' và đưa ra các góc nhìn định nghĩa khác nhau.", "💡 Gợi ý Tầng 1 (Định hướng bối cảnh): " & "Xác định cấu trúc tổng thể của bài đọc từ câu hỏi mở đầu đến các câu tiếp theo.")))) | P9: =IF(OR(G9="✅ Đúng", I9="✅ Đúng", K9="✅ Đúng"), "Mô hình cấu trúc: Question -> Multiple Explanations/Answers.", "🔒 Trả lời đúng để mở khóa Strategic Tip!")
A10: Q6 | B10: Main Purpose (Literary Narrative) | C10: The following text is adapted from the 1940 novel The Hamlet by William Faulkner. In rural Mississippi, a man is riding a horse toward the residence of someone he intends to meet with about a business matter. He was breathing hard but not because he had been galloping. On the contrary, since he had approached near enough to his destination to believe he could have seen smoke if there had been smoke, he had ridden slower and slower. Nevertheless he now sat the horse before the gap in the fence, breathing hard enough through his nose and even sweating a little, looking at the sagging broken-backed cabin set in its inevitable treeless and grassless plot and weathered to the color of an old bee-hive, with that expression of tense and rapid speculation of a man approaching a dud howitzer [artillery] shell. ©1967 by Estelle Faulkner and Jill Faulkner Summers | D10: Which choice best states the main purpose of the text? | E10: A. Lựa chọn A B. Lựa chọn B C. Lựa chọn C D. Lựa chọn D | G10: =IF(ISBLANK(F10), "⏳ Chờ đáp án", IF(UPPER(TRIM(F10))="D", "✅ Đúng", "❌ Sai")) | I10: =IF(ISBLANK(H10), "", IF(UPPER(TRIM(H10))="D", "✅ Đúng", "❌ Sai")) | K10: =IF(ISBLANK(J10), "", IF(UPPER(TRIM(J10))="D", "✅ Đúng", "❌ Sai")) | L10: =COUNTIF(G10, "❌ Sai") + COUNTIF(I10, "❌ Sai") + COUNTIF(K10, "❌ Sai") | M10: =IF(ISBLANK(F10), "⏳ Chờ làm", IF(G10="✅ Đúng", "✅ Đúng ngay L1", IF(I10="✅ Đúng", "✅ Đúng ở L2", IF(K10="✅ Đúng", "✅ Đúng ở L3", "❌ Chưa đúng sau 3 lần")))) | N10: =IF(G10="✅ Đúng", 1, IF(I10="✅ Đúng", 0.667, IF(K10="✅ Đúng", 0.333, 0))) | O10: =IF(ISBLANK(F10), "💡 Nhập đáp án vào Lần thử 1", IF(OR(G10="✅ Đúng", I10="✅ Đúng", K10="✅ Đúng"), "✨ Xuất sắc! Bạn đã làm đúng.", IF(NOT(ISBLANK(J10)), "💡 Gợi ý Tầng 3 (Chốt phương pháp): " & "Mục đích chính là thể hiện trạng thái tâm lý lo âu/căng thẳng của nhân vật qua hành vi cụ thể.", IF(NOT(ISBLANK(H10)), "💡 Gợi ý Tầng 2 (Manh mối cấu trúc & Loại trừ): " & "Chú ý các dấu hiệu như thở gấp, đổ mồ hôi và nét mặt căng thẳng trong bối cảnh truyện.", "💡 Gợi ý Tầng 1 (Định hướng bối cảnh): " & "Tập trung vào các chi tiết miêu tả cảm xúc và biểu hiện thể chất của nhân vật.")))) | P10: =IF(OR(G10="✅ Đúng", I10="✅ Đúng", K10="✅ Đúng"), "Văn xuôi hư cấu: Biểu hiện thể chất phản ánh trạng thái tâm lý nhân vật.", "🔒 Trả lời đúng để mở khóa Strategic Tip!")
A11: Q7 | B11: Main Purpose (Informational Text) | C11: Modern forestry offers diverse career opportunities that integrate scientific knowledge with hands-on environmental work. Arborists assess tree health and perform maintenance such as pruning to promote safety and prevent problems. Forestry technicians collect data on growth patterns and biodiversity in the wild. Forest ecologists conduct field research and analyze ecosystems to understand how forests respond to changes in weather patterns. With this blend of scientific understanding and practical application, forestry professionals address a variety of complex environmental challenges. | D11: Which choice best describes the main purpose of the text? | E11: A. Lựa chọn A B. Lựa chọn B C. Lựa chọn C D. Lựa chọn D | G11: =IF(ISBLANK(F11), "⏳ Chờ đáp án", IF(UPPER(TRIM(F11))="D", "✅ Đúng", "❌ Sai")) | I11: =IF(ISBLANK(H11), "", IF(UPPER(TRIM(H11))="D", "✅ Đúng", "❌ Sai")) | K11: =IF(ISBLANK(J11), "", IF(UPPER(TRIM(J11))="D", "✅ Đúng", "❌ Sai")) | L11: =COUNTIF(G11, "❌ Sai") + COUNTIF(I11, "❌ Sai") + COUNTIF(K11, "❌ Sai") | M11: =IF(ISBLANK(F11), "⏳ Chờ làm", IF(G11="✅ Đúng", "✅ Đúng ngay L1", IF(I11="✅ Đúng", "✅ Đúng ở L2", IF(K11="✅ Đúng", "✅ Đúng ở L3", "❌ Chưa đúng sau 3 lần")))) | N11: =IF(G11="✅ Đúng", 1, IF(I11="✅ Đúng", 0.667, IF(K11="✅ Đúng", 0.333, 0))) | O11: =IF(ISBLANK(F11), "💡 Nhập đáp án vào Lần thử 1", IF(OR(G11="✅ Đúng", I11="✅ Đúng", K11="✅ Đúng"), "✨ Xuất sắc! Bạn đã làm đúng.", IF(NOT(ISBLANK(J11)), "💡 Gợi ý Tầng 3 (Chốt phương pháp): " & "Mục đích là tổng quan các cơ hội nghề nghiệp đa dạng trong lĩnh vực được nêu.", IF(NOT(ISBLANK(H11)), "💡 Gợi ý Tầng 2 (Manh mối cấu trúc & Loại trừ): " & "Đoạn văn liệt kê các hướng đi công việc và cơ hội phát triển trong ngành lâm nghiệp.", "💡 Gợi ý Tầng 1 (Định hướng bối cảnh): " & "So sánh câu mở đầu và câu kết thúc của bài đọc để xác định chủ đề xuyên suốt.")))) | P11: =IF(OR(G11="✅ Đúng", I11="✅ Đúng", K11="✅ Đúng"), "Main Purpose = Topic (Forestry Careers) + So What? (Integrate science and practical work).", "🔒 Trả lời đúng để mở khóa Strategic Tip!")
A12: Q8 | B12: Detail & Literal Comprehension | C12: James Fong and his team claim to have discovered a new color, which they named olo. Olo is a very saturated blue-green color that can’t be seen with the human eye under natural conditions. In the human eye, long, medium, and short cones in the retina help sense bright light and color. Olo can only be seen by activating the medium cones alone. Fong and team activated these cones by using a targeted laser technology to stimulate just the medium cone cells. | D12: According to the text, how can the color olo be seen? | E12: A. Lựa chọn A B. Lựa chọn B C. Lựa chọn C D. Lựa chọn D | G12: =IF(ISBLANK(F12), "⏳ Chờ đáp án", IF(UPPER(TRIM(F12))="A", "✅ Đúng", "❌ Sai")) | I12: =IF(ISBLANK(H12), "", IF(UPPER(TRIM(H12))="A", "✅ Đúng", "❌ Sai")) | K12: =IF(ISBLANK(J12), "", IF(UPPER(TRIM(J12))="A", "✅ Đúng", "❌ Sai")) | L12: =COUNTIF(G12, "❌ Sai") + COUNTIF(I12, "❌ Sai") + COUNTIF(K12, "❌ Sai") | M12: =IF(ISBLANK(F12), "⏳ Chờ làm", IF(G12="✅ Đúng", "✅ Đúng ngay L1", IF(I12="✅ Đúng", "✅ Đúng ở L2", IF(K12="✅ Đúng", "✅ Đúng ở L3", "❌ Chưa đúng sau 3 lần")))) | N12: =IF(G12="✅ Đúng", 1, IF(I12="✅ Đúng", 0.667, IF(K12="✅ Đúng", 0.333, 0))) | O12: =IF(ISBLANK(F12), "💡 Nhập đáp án vào Lần thử 1", IF(OR(G12="✅ Đúng", I12="✅ Đúng", K12="✅ Đúng"), "✨ Xuất sắc! Bạn đã làm đúng.", IF(NOT(ISBLANK(J12)), "💡 Gợi ý Tầng 3 (Chốt phương pháp): " & "Chọn đáp án diễn đạt lại chính xác (paraphrase) điều kiện kích hoạt được nêu trực tiếp trên mặt chữ.", IF(NOT(ISBLANK(H12)), "💡 Gợi ý Tầng 2 (Manh mối cấu trúc & Loại trừ): " & "Đối chiếu trực tiếp chi tiết về điều kiện nhìn thấy được miêu tả ở phần giữa bài đọc.", "💡 Gợi ý Tầng 1 (Định hướng bối cảnh): " & "Xác định từ khóa tên riêng được đề cập trong câu hỏi và định vị câu chứa thông tin.")))) | P12: =IF(OR(G12="✅ Đúng", I12="✅ Đúng", K12="✅ Đúng"), "Literal Comprehension: Paraphrase đúng nguyên văn bài đọc, không suy diễn.", "🔒 Trả lời đúng để mở khóa Strategic Tip!")
A13: Q9 | B13: Quantitative Evidence (Graph) | C13: A student is collecting data about countries with volcanoes that have been active in the time since 1800 and in the time since 1960. The student records that Ethiopia has ______ | D13: Which choice most effectively uses data from the graph to complete the statement? | E13: A. Lựa chọn A B. Lựa chọn B C. Lựa chọn C D. Lựa chọn D | G13: =IF(ISBLANK(F13), "⏳ Chờ đáp án", IF(UPPER(TRIM(F13))="C", "✅ Đúng", "❌ Sai")) | I13: =IF(ISBLANK(H13), "", IF(UPPER(TRIM(H13))="C", "✅ Đúng", "❌ Sai")) | K13: =IF(ISBLANK(J13), "", IF(UPPER(TRIM(J13))="C", "✅ Đúng", "❌ Sai")) | L13: =COUNTIF(G13, "❌ Sai") + COUNTIF(I13, "❌ Sai") + COUNTIF(K13, "❌ Sai") | M13: =IF(ISBLANK(F13), "⏳ Chờ làm", IF(G13="✅ Đúng", "✅ Đúng ngay L1", IF(I13="✅ Đúng", "✅ Đúng ở L2", IF(K13="✅ Đúng", "✅ Đúng ở L3", "❌ Chưa đúng sau 3 lần")))) | N13: =IF(G13="✅ Đúng", 1, IF(I13="✅ Đúng", 0.667, IF(K13="✅ Đúng", 0.333, 0))) | O13: =IF(ISBLANK(F13), "💡 Nhập đáp án vào Lần thử 1", IF(OR(G13="✅ Đúng", I13="✅ Đúng", K13="✅ Đúng"), "✨ Xuất sắc! Bạn đã làm đúng.", IF(NOT(ISBLANK(J13)), "💡 Gợi ý Tầng 3 (Chốt phương pháp): " & "Chọn đáp án phản ánh đúng mối quan hệ lớn hơn/nhỏ hơn giữa hai số liệu trên đồ thị.", IF(NOT(ISBLANK(H13)), "💡 Gợi ý Tầng 2 (Manh mối cấu trúc & Loại trừ): " & "So sánh chiều cao của các cột đại diện cho số lượng núi lửa hoạt động giữa hai vùng.", "💡 Gợi ý Tầng 1 (Định hướng bối cảnh): " & "Quan sát biểu đồ và xác định đúng hai quốc gia cùng mốc thời gian từ năm 1960.")))) | P13: =IF(OR(G13="✅ Đúng", I13="✅ Đúng", K13="✅ Đúng"), "Đọc chính xác cột chú giải và số liệu tương ứng của hai quốc gia.", "🔒 Trả lời đúng để mở khóa Strategic Tip!")
A14: Q10 | B14: Command of Evidence (Quotation) | C14: Editor Jared Shurin’s enormous 2023 anthology The Big Book of Cyberpunk comprises 108 stories. Shurin’s volume is chronologically expansive, featuring such stories as James Tiptree Jr.’s “The Girl Who Was Plugged In” (1973) and Erica Satifka’s “Act of Providence” (2021). In his introduction, Shurin defines cyberpunk as a subgenre of speculative fiction concerning “the influence of technology on the scale, the pace, or the pattern of human affairs”; however, some critics assert that cyberpunk is a literary movement that is in large part aesthetic rather than idea driven. | D14: Which quotation from a literary critic would be the most effective evidence in support of the underlined claim? | E14: A. Lựa chọn A B. Lựa chọn B C. Lựa chọn C D. Lựa chọn D | G14: =IF(ISBLANK(F14), "⏳ Chờ đáp án", IF(UPPER(TRIM(F14))="D", "✅ Đúng", "❌ Sai")) | I14: =IF(ISBLANK(H14), "", IF(UPPER(TRIM(H14))="D", "✅ Đúng", "❌ Sai")) | K14: =IF(ISBLANK(J14), "", IF(UPPER(TRIM(J14))="D", "✅ Đúng", "❌ Sai")) | L14: =COUNTIF(G14, "❌ Sai") + COUNTIF(I14, "❌ Sai") + COUNTIF(K14, "❌ Sai") | M14: =IF(ISBLANK(F14), "⏳ Chờ làm", IF(G14="✅ Đúng", "✅ Đúng ngay L1", IF(I14="✅ Đúng", "✅ Đúng ở L2", IF(K14="✅ Đúng", "✅ Đúng ở L3", "❌ Chưa đúng sau 3 lần")))) | N14: =IF(G14="✅ Đúng", 1, IF(I14="✅ Đúng", 0.667, IF(K14="✅ Đúng", 0.333, 0))) | O14: =IF(ISBLANK(F14), "💡 Nhập đáp án vào Lần thử 1", IF(OR(G14="✅ Đúng", I14="✅ Đúng", K14="✅ Đúng"), "✨ Xuất sắc! Bạn đã làm đúng.", IF(NOT(ISBLANK(J14)), "💡 Gợi ý Tầng 3 (Chốt phương pháp): " & "Loại trừ các trích dẫn chỉ nói về chức năng kỹ thuật; chọn câu nhấn mạnh khía cạnh phong cách/thẩm mỹ.", IF(NOT(ISBLANK(H14)), "💡 Gợi ý Tầng 2 (Manh mối cấu trúc & Loại trừ): " & "Tìm câu trích dẫn chứa các từ miêu tả dáng vẻ bên ngoài, phụ kiện hoặc yếu tố văn hóa đại chúng.", "💡 Gợi ý Tầng 1 (Định hướng bối cảnh): " & "Đọc kỹ yêu cầu câu hỏi về yếu tố thẩm mỹ hoặc biểu tượng phong cách.")))) | P14: =IF(OR(G14="✅ Đúng", I14="✅ Đúng", K14="✅ Đúng"), "Bằng chứng hỗ trợ phải trực tiếp chứng minh tính chất 'aesthetic' (thẩm mỹ).", "🔒 Trả lời đúng để mở khóa Strategic Tip!")
A15: Q11 | B15: Command of Evidence (Table Data) | C15: Employment in Tribal Economies in December 2017 and December 2023 by Sector Economic sector Approximate total number of employees, 2017 Percentage of workforce, 2017 Approximate total number of employees, 2023 Percentage of workforce, 2023 Business sector (all tribal businesses) 220,700 66.0% 232,300 65.4% Leisure and hospitality businesses 185,100 55.3% 192,300 54.2% Education and healthcare businesses 19,100 5.7% 21,600 6.1% Other businesses 16,500 5.0% 18,400 5.1% Public sector (tribal government and public administration) 113,800 34.0% 122,700 34.6% Tribal nations employ a large percentage of their populations in tribally owned businesses as well as in government and public administration. This is especially true in Oklahoma and other states with robust tribal economies and large Native populations. Between end-of-year 2017 and end-of-year 2023, the percentage of tribal employees working in the public sector increased, from 34.0% to 34.6%, while the percentage working in the business sector declined from 66.0% to 65.4%. | D15: Which statement about the decline in the percentage of tribal employees working in the business sector is best supported by information in the table? | E15: A. Lựa chọn A B. Lựa chọn B C. Lựa chọn C D. Lựa chọn D | G15: =IF(ISBLANK(F15), "⏳ Chờ đáp án", IF(UPPER(TRIM(F15))="A", "✅ Đúng", "❌ Sai")) | I15: =IF(ISBLANK(H15), "", IF(UPPER(TRIM(H15))="A", "✅ Đúng", "❌ Sai")) | K15: =IF(ISBLANK(J15), "", IF(UPPER(TRIM(J15))="A", "✅ Đúng", "❌ Sai")) | L15: =COUNTIF(G15, "❌ Sai") + COUNTIF(I15, "❌ Sai") + COUNTIF(K15, "❌ Sai") | M15: =IF(ISBLANK(F15), "⏳ Chờ làm", IF(G15="✅ Đúng", "✅ Đúng ngay L1", IF(I15="✅ Đúng", "✅ Đúng ở L2", IF(K15="✅ Đúng", "✅ Đúng ở L3", "❌ Chưa đúng sau 3 lần")))) | N15: =IF(G15="✅ Đúng", 1, IF(I15="✅ Đúng", 0.667, IF(K15="✅ Đúng", 0.333, 0))) | O15: =IF(ISBLANK(F15), "💡 Nhập đáp án vào Lần thử 1", IF(OR(G15="✅ Đúng", I15="✅ Đúng", K15="✅ Đúng"), "✨ Xuất sắc! Bạn đã làm đúng.", IF(NOT(ISBLANK(J15)), "💡 Gợi ý Tầng 3 (Chốt phương pháp): " & "Chọn đáp án nêu đúng sự thay đổi tăng/giảm dựa trên phép trừ số liệu chính xác trong bảng.", IF(NOT(ISBLANK(H15)), "💡 Gợi ý Tầng 2 (Manh mối cấu trúc & Loại trừ): " & "So sánh giá trị nhân viên thực tế giữa các mốc năm trong ngành kinh doanh.", "💡 Gợi ý Tầng 1 (Định hướng bối cảnh): " & "Định vị ngành nghề và khoảng thời gian được đề cập trong bảng số liệu.")))) | P15: =IF(OR(G15="✅ Đúng", I15="✅ Đúng", K15="✅ Đúng"), "Tỷ lệ % giảm không có nghĩa là số lượng tuyệt đối giảm nếu tổng quy mô tăng.", "🔒 Trả lời đúng để mở khóa Strategic Tip!")
A16: Q12 | B16: Command of Evidence (Chart Interpretation) | C16: While US public charities, like Commonfund, must file Form 990 yearly with the IRS, private foundations, such as Lilly Endowment Inc., must file a different form, 990-PF. In addition, foundations that engage in certain prohibited activities must also file Form 4720 and pay a penalty tax on the money involved. Private foundations are prohibited from holding excess interests in a business enterprise, “self-dealing” (conducting activities that benefit foundation insiders), making taxable expenditures such as grants to noncharitable entities, and failing to cross a required threshold in making charitable distributions from income. Out of the organizations that filed Form 990-PF in the years 2003–2005, ______ | D16: Which choice most effectively uses data from the graph to complete the assertion? | E16: A. Lựa chọn A B. Lựa chọn B C. Lựa chọn C D. Lựa chọn D | G16: =IF(ISBLANK(F16), "⏳ Chờ đáp án", IF(UPPER(TRIM(F16))="C", "✅ Đúng", "❌ Sai")) | I16: =IF(ISBLANK(H16), "", IF(UPPER(TRIM(H16))="C", "✅ Đúng", "❌ Sai")) | K16: =IF(ISBLANK(J16), "", IF(UPPER(TRIM(J16))="C", "✅ Đúng", "❌ Sai")) | L16: =COUNTIF(G16, "❌ Sai") + COUNTIF(I16, "❌ Sai") + COUNTIF(K16, "❌ Sai") | M16: =IF(ISBLANK(F16), "⏳ Chờ làm", IF(G16="✅ Đúng", "✅ Đúng ngay L1", IF(I16="✅ Đúng", "✅ Đúng ở L2", IF(K16="✅ Đúng", "✅ Đúng ở L3", "❌ Chưa đúng sau 3 lần")))) | N16: =IF(G16="✅ Đúng", 1, IF(I16="✅ Đúng", 0.667, IF(K16="✅ Đúng", 0.333, 0))) | O16: =IF(ISBLANK(F16), "💡 Nhập đáp án vào Lần thử 1", IF(OR(G16="✅ Đúng", I16="✅ Đúng", K16="✅ Đúng"), "✨ Xuất sắc! Bạn đã làm đúng.", IF(NOT(ISBLANK(J16)), "💡 Gợi ý Tầng 3 (Chốt phương pháp): " & "Chọn đáp án phản ánh chính xác xu hướng biến động số liệu được thể hiện trên đồ thị.", IF(NOT(ISBLANK(H16)), "💡 Gợi ý Tầng 2 (Manh mối cấu trúc & Loại trừ): " & "So sánh tỉ lệ giữa hai năm được hỏi (2003 và 2005) để xem năm nào cao hơn.", "💡 Gợi ý Tầng 1 (Định hướng bối cảnh): " & "Chú ý chỉ số phần trăm do 'undistributed income' trên biểu đồ qua các mốc năm.")))) | P16: =IF(OR(G16="✅ Đúng", I16="✅ Đúng", K16="✅ Đúng"), "Đọc đúng cột năm (2003 vs 2005) và nhóm lý do bị phạt.", "🔒 Trả lời đúng để mở khóa Strategic Tip!")
A17: Q13 | B17: Command of Evidence (Literary Text) | C17: Philoctetes is a play by Sophocles that was first performed in 409 BCE. In the play, Odysseus and Neoptolemus must retrieve Philoctetes—a master archer who is believed necessary for the Greeks to win the Trojan War—from a cave on a deserted island where Odysseus and others had abandoned him with a debilitating injury earlier in the war. Odysseus suggests that the plan for returning with Philoctetes rests on Neoptolemus not having been part of the group that abandoned him: ______ | D17: Which quotation from Philoctetes most effectively illustrates the claim? | E17: A. Lựa chọn A B. Lựa chọn B C. Lựa chọn C D. Lựa chọn D | G17: =IF(ISBLANK(F17), "⏳ Chờ đáp án", IF(UPPER(TRIM(F17))="C", "✅ Đúng", "❌ Sai")) | I17: =IF(ISBLANK(H17), "", IF(UPPER(TRIM(H17))="C", "✅ Đúng", "❌ Sai")) | K17: =IF(ISBLANK(J17), "", IF(UPPER(TRIM(J17))="C", "✅ Đúng", "❌ Sai")) | L17: =COUNTIF(G17, "❌ Sai") + COUNTIF(I17, "❌ Sai") + COUNTIF(K17, "❌ Sai") | M17: =IF(ISBLANK(F17), "⏳ Chờ làm", IF(G17="✅ Đúng", "✅ Đúng ngay L1", IF(I17="✅ Đúng", "✅ Đúng ở L2", IF(K17="✅ Đúng", "✅ Đúng ở L3", "❌ Chưa đúng sau 3 lần")))) | N17: =IF(G17="✅ Đúng", 1, IF(I17="✅ Đúng", 0.667, IF(K17="✅ Đúng", 0.333, 0))) | O17: =IF(ISBLANK(F17), "💡 Nhập đáp án vào Lần thử 1", IF(OR(G17="✅ Đúng", I17="✅ Đúng", K17="✅ Đúng"), "✨ Xuất sắc! Bạn đã làm đúng.", IF(NOT(ISBLANK(J17)), "💡 Gợi ý Tầng 3 (Chốt phương pháp): " & "Chọn trích dẫn thể hiện rõ việc nhân vật không tham gia vào hành động bỏ rơi trước đó.", IF(NOT(ISBLANK(H17)), "💡 Gợi ý Tầng 2 (Manh mối cấu trúc & Loại trừ): " & "Tìm câu thoại hoặc lời kể giải thích lý do nhân vật không bị coi là người phản bội.", "💡 Gợi ý Tầng 1 (Định hướng bối cảnh): " & "Xác định nguyên nhân dẫn đến sự tin tưởng của nhân vật được hỏi trong tác phẩm.")))) | P17: =IF(OR(G17="✅ Đúng", I17="✅ Đúng", K17="✅ Đúng"), "Chọn câu thoại thể hiện rõ luận điểm Neoptolemus không thuộc nhóm cũ.", "🔒 Trả lời đúng để mở khóa Strategic Tip!")
A18: Q14 | B18: Text Completion / Logical Inference | C18: Louis-Ferdinand Céline’s 1932 novel Journey to the End of the Night is regularly described as autobiographical. That characterization is apt—there are many parallels between the experiences of the novel’s protagonist, Ferdinand Bardamu, and those of Céline—but it should not be taken to mean that every person or event depicted in Journey to the End of the Night has a real-life analogue. Much of the novel is pure invention, and readers who overlook this fact and instead focus excessively on correspondences between the novel and Céline’s life can thus ______ | D18: Which choice most logically completes the text? | E18: A. Lựa chọn A B. Lựa chọn B C. Lựa chọn C D. Lựa chọn D | G18: =IF(ISBLANK(F18), "⏳ Chờ đáp án", IF(UPPER(TRIM(F18))="A", "✅ Đúng", "❌ Sai")) | I18: =IF(ISBLANK(H18), "", IF(UPPER(TRIM(H18))="A", "✅ Đúng", "❌ Sai")) | K18: =IF(ISBLANK(J18), "", IF(UPPER(TRIM(J18))="A", "✅ Đúng", "❌ Sai")) | L18: =COUNTIF(G18, "❌ Sai") + COUNTIF(I18, "❌ Sai") + COUNTIF(K18, "❌ Sai") | M18: =IF(ISBLANK(F18), "⏳ Chờ làm", IF(G18="✅ Đúng", "✅ Đúng ngay L1", IF(I18="✅ Đúng", "✅ Đúng ở L2", IF(K18="✅ Đúng", "✅ Đúng ở L3", "❌ Chưa đúng sau 3 lần")))) | N18: =IF(G18="✅ Đúng", 1, IF(I18="✅ Đúng", 0.667, IF(K18="✅ Đúng", 0.333, 0))) | O18: =IF(ISBLANK(F18), "💡 Nhập đáp án vào Lần thử 1", IF(OR(G18="✅ Đúng", I18="✅ Đúng", K18="✅ Đúng"), "✨ Xuất sắc! Bạn đã làm đúng.", IF(NOT(ISBLANK(J18)), "💡 Gợi ý Tầng 3 (Chốt phương pháp): " & "Chọn câu kết luận chỉ ra sự thiếu sót trong việc đánh giá toàn diện tác phẩm nếu chỉ nhìn một chiều.", IF(NOT(ISBLANK(H18)), "💡 Gợi ý Tầng 2 (Manh mối cấu trúc & Loại trừ): " & "Chú ý từ nối đối lập chỉ ra hậu quả của việc bỏ qua khía cạnh hư cấu trong nghiên cứu.", "💡 Gợi ý Tầng 1 (Định hướng bối cảnh): " & "Xác định mối quan hệ logic giữa việc tập trung vào yếu tố tự thuật và yếu tố sáng tác.")))) | P18: =IF(OR(G18="✅ Đúng", I18="✅ Đúng", K18="✅ Đúng"), "Suy luận logic: Xem nhẹ 'pure invention' -> Bỏ qua tính sáng tạo (creativity).", "🔒 Trả lời đúng để mở khóa Strategic Tip!")
A19: Q15 | B19: Text Completion / Inference | C19: Last-mile delivery, the final stage in the delivery of products to customers, is subject to increasing pressure as consumers place greater emphasis on convenience and immediacy, increasingly expecting next-day delivery. In response to this challenge and others, such as the increasing volume of parcels to be delivered, delivery companies are continually looking for ways to make last-mile delivery more efficient. One advance in last-mile delivery is the use of self-service lockers (containers where consumers can pick up their parcels using a unique code). This approach, while promising, also introduces new obstacles (e.g., convenient placement of self-service lockers is challenging). It is therefore likely that ______ | D19: Which choice most logically completes the text? | E19: A. Lựa chọn A B. Lựa chọn B C. Lựa chọn C D. Lựa chọn D | G19: =IF(ISBLANK(F19), "⏳ Chờ đáp án", IF(UPPER(TRIM(F19))="A", "✅ Đúng", "❌ Sai")) | I19: =IF(ISBLANK(H19), "", IF(UPPER(TRIM(H19))="A", "✅ Đúng", "❌ Sai")) | K19: =IF(ISBLANK(J19), "", IF(UPPER(TRIM(J19))="A", "✅ Đúng", "❌ Sai")) | L19: =COUNTIF(G19, "❌ Sai") + COUNTIF(I19, "❌ Sai") + COUNTIF(K19, "❌ Sai") | M19: =IF(ISBLANK(F19), "⏳ Chờ làm", IF(G19="✅ Đúng", "✅ Đúng ngay L1", IF(I19="✅ Đúng", "✅ Đúng ở L2", IF(K19="✅ Đúng", "✅ Đúng ở L3", "❌ Chưa đúng sau 3 lần")))) | N19: =IF(G19="✅ Đúng", 1, IF(I19="✅ Đúng", 0.667, IF(K19="✅ Đúng", 0.333, 0))) | O19: =IF(ISBLANK(F19), "💡 Nhập đáp án vào Lần thử 1", IF(OR(G19="✅ Đúng", I19="✅ Đúng", K19="✅ Đúng"), "✨ Xuất sắc! Bạn đã làm đúng.", IF(NOT(ISBLANK(J19)), "💡 Gợi ý Tầng 3 (Chốt phương pháp): " & "Chọn kết luận nối tiếp hợp lý, thể hiện sự suy giảm hoặc thay đổi hành vi tương ứng.", IF(NOT(ISBLANK(H19)), "💡 Gợi ý Tầng 2 (Manh mối cấu trúc & Loại trừ): " & "Chú ý các bằng chứng được đưa ra ở câu trước về sự thay đổi nguồn thức ăn.", "💡 Gợi ý Tầng 1 (Định hướng bối cảnh): " & "Phân tích lập luận của tác giả về tác động của biến đổi khí hậu đối với loài động vật.")))) | P19: =IF(OR(G19="✅ Đúng", I19="✅ Đúng", K19="✅ Đúng"), "Kết luận hợp lý: Giải pháp hiện tại gặp thách thức -> Cần tiếp tục thử nghiệm ý tưởng mới.", "🔒 Trả lời đúng để mở khóa Strategic Tip!")
A20: Q16 | B20: Standard English Conventions (Relative Clauses) | C20: With an average summer temperature of 82.5 degrees Fahrenheit, Nicosia is one European ______ many travelers recommend, especially from June to September. | D20: Which choice completes the text so that it conforms to the conventions of Standard English? | E20: A. Lựa chọn A B. Lựa chọn B C. Lựa chọn C D. Lựa chọn D | G20: =IF(ISBLANK(F20), "⏳ Chờ đáp án", IF(UPPER(TRIM(F20))="C", "✅ Đúng", "❌ Sai")) | I20: =IF(ISBLANK(H20), "", IF(UPPER(TRIM(H20))="C", "✅ Đúng", "❌ Sai")) | K20: =IF(ISBLANK(J20), "", IF(UPPER(TRIM(J20))="C", "✅ Đúng", "❌ Sai")) | L20: =COUNTIF(G20, "❌ Sai") + COUNTIF(I20, "❌ Sai") + COUNTIF(K20, "❌ Sai") | M20: =IF(ISBLANK(F20), "⏳ Chờ làm", IF(G20="✅ Đúng", "✅ Đúng ngay L1", IF(I20="✅ Đúng", "✅ Đúng ở L2", IF(K20="✅ Đúng", "✅ Đúng ở L3", "❌ Chưa đúng sau 3 lần")))) | N20: =IF(G20="✅ Đúng", 1, IF(I20="✅ Đúng", 0.667, IF(K20="✅ Đúng", 0.333, 0))) | O20: =IF(ISBLANK(F20), "💡 Nhập đáp án vào Lần thử 1", IF(OR(G20="✅ Đúng", I20="✅ Đúng", K20="✅ Đúng"), "✨ Xuất sắc! Bạn đã làm đúng.", IF(NOT(ISBLANK(J20)), "💡 Gợi ý Tầng 3 (Chốt phương pháp): " & "Loại bỏ các đại từ quan hệ không phù hợp; chọn cấu trúc ngữ pháp chuẩn xác.", IF(NOT(ISBLANK(H20)), "💡 Gợi ý Tầng 2 (Manh mối cấu trúc & Loại trừ): " & "Kiểm tra xem động từ trong mệnh đề quan hệ chia ở số ít hay số nhiều dựa vào danh từ trung tâm.", "💡 Gợi ý Tầng 1 (Định hướng bối cảnh): " & "Xác định mệnh đề quan hệ bổ nghĩa cho danh từ chỉ vật hay chỉ người đứng trước.")))) | P20: =IF(OR(G20="✅ Đúng", I20="✅ Đúng", K20="✅ Đúng"), "Dùng 'that' không dấu phẩy cho mệnh đề quan hệ giới hạn.", "🔒 Trả lời đúng để mở khóa Strategic Tip!")
A21: Q17 | B21: Standard English Conventions (Verb Tense & Progress) | C21: Nanoengineers have developed synthesized mesoporous silica nanoparticles that are used to transport genes and medicines to specific cells in the body. As nanotechnology evolves, medical technology ______ to evolve as well. | D21: Which choice completes the text so that it conforms to the conventions of Standard English? | E21: A. Lựa chọn A B. Lựa chọn B C. Lựa chọn C D. Lựa chọn D | G21: =IF(ISBLANK(F21), "⏳ Chờ đáp án", IF(UPPER(TRIM(F21))="D", "✅ Đúng", "❌ Sai")) | I21: =IF(ISBLANK(H21), "", IF(UPPER(TRIM(H21))="D", "✅ Đúng", "❌ Sai")) | K21: =IF(ISBLANK(J21), "", IF(UPPER(TRIM(J21))="D", "✅ Đúng", "❌ Sai")) | L21: =COUNTIF(G21, "❌ Sai") + COUNTIF(I21, "❌ Sai") + COUNTIF(K21, "❌ Sai") | M21: =IF(ISBLANK(F21), "⏳ Chờ làm", IF(G21="✅ Đúng", "✅ Đúng ngay L1", IF(I21="✅ Đúng", "✅ Đúng ở L2", IF(K21="✅ Đúng", "✅ Đúng ở L3", "❌ Chưa đúng sau 3 lần")))) | N21: =IF(G21="✅ Đúng", 1, IF(I21="✅ Đúng", 0.667, IF(K21="✅ Đúng", 0.333, 0))) | O21: =IF(ISBLANK(F21), "💡 Nhập đáp án vào Lần thử 1", IF(OR(G21="✅ Đúng", I21="✅ Đúng", K21="✅ Đúng"), "✨ Xuất sắc! Bạn đã làm đúng.", IF(NOT(ISBLANK(J21)), "💡 Gợi ý Tầng 3 (Chốt phương pháp): " & "Chọn dạng động từ thể hiện sự tiếp diễn hoặc hoàn thành phù hợp với bối cảnh.", IF(NOT(ISBLANK(H21)), "💡 Gợi ý Tầng 2 (Manh mối cấu trúc & Loại trừ): " & "Đối chiếu thì của các động từ xung quanh để bảo đảm tính nhất quán về thời gian.", "💡 Gợi ý Tầng 1 (Định hướng bối cảnh): " & "Xác định mốc thời gian và tính liên tục của hành động trong bài đọc.")))) | P21: =IF(OR(G21="✅ Đúng", I21="✅ Đúng", K21="✅ Đúng"), "Sự tương thích thì: As [Present], [Future].", "🔒 Trả lời đúng để mở khóa Strategic Tip!")
A22: Q18 | B22: Standard English Conventions (Punctuation / Dashes) | C22: To more easily balance the weight of her body on her toes while performing the demanding pointe work that became increasingly common in early 20th-century ballet, internationally known ballerina Anna Pavlova redesigned her pointe shoes. The modifications she made—adding a stiffened leather sole and hardened toe ______ began the modernization of ballet’s iconic footwear. | D22: Which choice completes the text so that it conforms to the conventions of Standard English? | E22: A. Lựa chọn A B. Lựa chọn B C. Lựa chọn C D. Lựa chọn D | G22: =IF(ISBLANK(F22), "⏳ Chờ đáp án", IF(UPPER(TRIM(F22))="B", "✅ Đúng", "❌ Sai")) | I22: =IF(ISBLANK(H22), "", IF(UPPER(TRIM(H22))="B", "✅ Đúng", "❌ Sai")) | K22: =IF(ISBLANK(J22), "", IF(UPPER(TRIM(J22))="B", "✅ Đúng", "❌ Sai")) | L22: =COUNTIF(G22, "❌ Sai") + COUNTIF(I22, "❌ Sai") + COUNTIF(K22, "❌ Sai") | M22: =IF(ISBLANK(F22), "⏳ Chờ làm", IF(G22="✅ Đúng", "✅ Đúng ngay L1", IF(I22="✅ Đúng", "✅ Đúng ở L2", IF(K22="✅ Đúng", "✅ Đúng ở L3", "❌ Chưa đúng sau 3 lần")))) | N22: =IF(G22="✅ Đúng", 1, IF(I22="✅ Đúng", 0.667, IF(K22="✅ Đúng", 0.333, 0))) | O22: =IF(ISBLANK(F22), "💡 Nhập đáp án vào Lần thử 1", IF(OR(G22="✅ Đúng", I22="✅ Đúng", K22="✅ Đúng"), "✨ Xuất sắc! Bạn đã làm đúng.", IF(NOT(ISBLANK(J22)), "💡 Gợi ý Tầng 3 (Chốt phương pháp): " & "Loại bỏ các phương án dùng hỗn hợp dấu phẩy và gạch ngang không đồng bộ.", IF(NOT(ISBLANK(H22)), "💡 Gợi ý Tầng 2 (Manh mối cấu trúc & Loại trừ): " & "Nhớ quy tắc cặp dấu tương đương: nếu đã mở đầu bằng dấu gạch ngang thì phải đóng bằng dấu gạch ngang.", "💡 Gợi ý Tầng 1 (Định hướng bối cảnh): " & "Xác định thành phần bổ sung không thiết yếu (non-essential clause) trong câu.")))) | P22: =IF(OR(G22="✅ Đúng", I22="✅ Đúng", K22="✅ Đúng"), "Dấu gạch ngang đi theo cặp: — [thông tin bổ sung] —.", "🔒 Trả lời đúng để mở khóa Strategic Tip!")
A23: Q19 | B23: Standard English Conventions (Colons) | C23: Archaeological evidence indicates that board games have existed in human societies for at least five millennia, with examples discovered in the tombs of ancient Egypt and the ruins of Mesopotamia. The purpose of these ancient games was ______ provide entertainment during leisure time, to reflect cultural beliefs, and to develop strategic thinking skills among players. | D23: Which choice completes the text so that it conforms to the conventions of Standard English? | E23: A. Lựa chọn A B. Lựa chọn B C. Lựa chọn C D. Lựa chọn D | G23: =IF(ISBLANK(F23), "⏳ Chờ đáp án", IF(UPPER(TRIM(F23))="B", "✅ Đúng", "❌ Sai")) | I23: =IF(ISBLANK(H23), "", IF(UPPER(TRIM(H23))="B", "✅ Đúng", "❌ Sai")) | K23: =IF(ISBLANK(J23), "", IF(UPPER(TRIM(J23))="B", "✅ Đúng", "❌ Sai")) | L23: =COUNTIF(G23, "❌ Sai") + COUNTIF(I23, "❌ Sai") + COUNTIF(K23, "❌ Sai") | M23: =IF(ISBLANK(F23), "⏳ Chờ làm", IF(G23="✅ Đúng", "✅ Đúng ngay L1", IF(I23="✅ Đúng", "✅ Đúng ở L2", IF(K23="✅ Đúng", "✅ Đúng ở L3", "❌ Chưa đúng sau 3 lần")))) | N23: =IF(G23="✅ Đúng", 1, IF(I23="✅ Đúng", 0.667, IF(K23="✅ Đúng", 0.333, 0))) | O23: =IF(ISBLANK(F23), "💡 Nhập đáp án vào Lần thử 1", IF(OR(G23="✅ Đúng", I23="✅ Đúng", K23="✅ Đúng"), "✨ Xuất sắc! Bạn đã làm đúng.", IF(NOT(ISBLANK(J23)), "💡 Gợi ý Tầng 3 (Chốt phương pháp): " & "Loại bỏ phương án dùng dấu phẩy nối hai mệnh đề độc lập (lỗi comma splice).", IF(NOT(ISBLANK(H23)), "💡 Gợi ý Tầng 2 (Manh mối cấu trúc & Loại trừ): " & "Dấu hai chấm được dùng để giải thích hoặc chi tiết hóa nội dung đã nêu ở mệnh đề độc lập trước đó.", "💡 Gợi ý Tầng 1 (Định hướng bối cảnh): " & "Kiểm tra xem vế trước vị trí cần điền có phải là một mệnh đề độc lập hoàn chỉnh hay không.")))) | P23: =IF(OR(G23="✅ Đúng", I23="✅ Đúng", K23="✅ Đúng"), "Dấu hai chấm (:) báo hiệu danh sách giải thích phía sau.", "🔒 Trả lời đúng để mở khóa Strategic Tip!")
A24: Q20 | B24: Standard English Conventions (Semicolons & Colons) | C24: Extensive radiocarbon dating of reed samples from Caral confirmed Ruth Shady Solís’s hypothesis about the Peruvian site’s ______ nearly 5,000 years ago, the ancient city preceded the Olmec civilization to the north by a full millennium, a revelation that fundamentally altered our understanding of urban development in the Western Hemisphere. | D24: Which choice completes the text so that it conforms to the conventions of Standard English? | E24: A. Lựa chọn A B. Lựa chọn B C. Lựa chọn C D. Lựa chọn D | G24: =IF(ISBLANK(F24), "⏳ Chờ đáp án", IF(UPPER(TRIM(F24))="B", "✅ Đúng", "❌ Sai")) | I24: =IF(ISBLANK(H24), "", IF(UPPER(TRIM(H24))="B", "✅ Đúng", "❌ Sai")) | K24: =IF(ISBLANK(J24), "", IF(UPPER(TRIM(J24))="B", "✅ Đúng", "❌ Sai")) | L24: =COUNTIF(G24, "❌ Sai") + COUNTIF(I24, "❌ Sai") + COUNTIF(K24, "❌ Sai") | M24: =IF(ISBLANK(F24), "⏳ Chờ làm", IF(G24="✅ Đúng", "✅ Đúng ngay L1", IF(I24="✅ Đúng", "✅ Đúng ở L2", IF(K24="✅ Đúng", "✅ Đúng ở L3", "❌ Chưa đúng sau 3 lần")))) | N24: =IF(G24="✅ Đúng", 1, IF(I24="✅ Đúng", 0.667, IF(K24="✅ Đúng", 0.333, 0))) | O24: =IF(ISBLANK(F24), "💡 Nhập đáp án vào Lần thử 1", IF(OR(G24="✅ Đúng", I24="✅ Đúng", K24="✅ Đúng"), "✨ Xuất sắc! Bạn đã làm đúng.", IF(NOT(ISBLANK(J24)), "💡 Gợi ý Tầng 3 (Chốt phương pháp): " & "Loại bỏ phương án chỉ dùng dấu phẩy đơn lẻ giữa hai mệnh đề độc lập.", IF(NOT(ISBLANK(H24)), "💡 Gợi ý Tầng 2 (Manh mối cấu trúc & Loại trừ): " & "Nếu hai mệnh đề độc lập không có liên từ FANBOYS thì phải dùng dấu chấm phẩy hoặc dấu chấm.", "💡 Gợi ý Tầng 1 (Định hướng bối cảnh): " & "Phân tích mối quan hệ giữa hai mệnh đề độc lập đứng trước và sau vị trí khoảng trống.")))) | P24: =IF(OR(G24="✅ Đúng", I24="✅ Đúng", K24="✅ Đúng"), "Dấu hai chấm nối 2 mệnh đề độc lập khi mệnh đề 2 giải thích cho mệnh đề 1.", "🔒 Trả lời đúng để mở khóa Strategic Tip!")
A25: Q21 | B25: Standard English Conventions (Subject-Verb Agreement) | C25: Chemists investigating the properties of coal tar in the mid-nineteenth century discovered compounds that led to the creation of vibrant artificial colorants. Commercial applications of this new synthetic dye technology—beginning with the purple dye called mauve, discovered by William Perkin in 1856—______ responsible for launching what one science historian calls a “manufacturing revolution based on chemistry.” | D25: Which choice completes the text so that it conforms to the conventions of Standard English? | E25: A. Lựa chọn A B. Lựa chọn B C. Lựa chọn C D. Lựa chọn D | G25: =IF(ISBLANK(F25), "⏳ Chờ đáp án", IF(UPPER(TRIM(F25))="C", "✅ Đúng", "❌ Sai")) | I25: =IF(ISBLANK(H25), "", IF(UPPER(TRIM(H25))="C", "✅ Đúng", "❌ Sai")) | K25: =IF(ISBLANK(J25), "", IF(UPPER(TRIM(J25))="C", "✅ Đúng", "❌ Sai")) | L25: =COUNTIF(G25, "❌ Sai") + COUNTIF(I25, "❌ Sai") + COUNTIF(K25, "❌ Sai") | M25: =IF(ISBLANK(F25), "⏳ Chờ làm", IF(G25="✅ Đúng", "✅ Đúng ngay L1", IF(I25="✅ Đúng", "✅ Đúng ở L2", IF(K25="✅ Đúng", "✅ Đúng ở L3", "❌ Chưa đúng sau 3 lần")))) | N25: =IF(G25="✅ Đúng", 1, IF(I25="✅ Đúng", 0.667, IF(K25="✅ Đúng", 0.333, 0))) | O25: =IF(ISBLANK(F25), "💡 Nhập đáp án vào Lần thử 1", IF(OR(G25="✅ Đúng", I25="✅ Đúng", K25="✅ Đúng"), "✨ Xuất sắc! Bạn đã làm đúng.", IF(NOT(ISBLANK(J25)), "💡 Gợi ý Tầng 3 (Chốt phương pháp): " & "Chọn dạng động từ hòa hợp chính xác về số với chủ ngữ trung tâm.", IF(NOT(ISBLANK(H25)), "💡 Gợi ý Tầng 2 (Manh mối cấu trúc & Loại trừ): " & "Kiểm tra xem chủ ngữ chính là danh từ số ít hay số nhiều.", "💡 Gợi ý Tầng 1 (Định hướng bối cảnh): " & "Xác định chủ ngữ chính của câu bằng cách gạch bỏ các cụm giới từ nhiễu đứng giữa.")))) | P25: =IF(OR(G25="✅ Đúng", I25="✅ Đúng", K25="✅ Đúng"), "Gạch bỏ thông tin xen giữa trong hai dấu gạch ngang để xác định chủ ngữ chính.", "🔒 Trả lời đúng để mở khóa Strategic Tip!")
A26: Q22 | B26: Transitions (Sequence & Step) | C26: How does a clear evening become foggy? First, the ground releases heat, which radiates upward. This causes the air near the ground to cool. ______ tiny water droplets begin to form as the cooling air reaches its dew point and can no longer hold its moisture as invisible vapor. Finally, as more droplets accumulate, a visible layer of fog develops close to the ground. | D26: Which choice completes the text with the most logical transition? | E26: A. Lựa chọn A B. Lựa chọn B C. Lựa chọn C D. Lựa chọn D | G26: =IF(ISBLANK(F26), "⏳ Chờ đáp án", IF(UPPER(TRIM(F26))="D", "✅ Đúng", "❌ Sai")) | I26: =IF(ISBLANK(H26), "", IF(UPPER(TRIM(H26))="D", "✅ Đúng", "❌ Sai")) | K26: =IF(ISBLANK(J26), "", IF(UPPER(TRIM(J26))="D", "✅ Đúng", "❌ Sai")) | L26: =COUNTIF(G26, "❌ Sai") + COUNTIF(I26, "❌ Sai") + COUNTIF(K26, "❌ Sai") | M26: =IF(ISBLANK(F26), "⏳ Chờ làm", IF(G26="✅ Đúng", "✅ Đúng ngay L1", IF(I26="✅ Đúng", "✅ Đúng ở L2", IF(K26="✅ Đúng", "✅ Đúng ở L3", "❌ Chưa đúng sau 3 lần")))) | N26: =IF(G26="✅ Đúng", 1, IF(I26="✅ Đúng", 0.667, IF(K26="✅ Đúng", 0.333, 0))) | O26: =IF(ISBLANK(F26), "💡 Nhập đáp án vào Lần thử 1", IF(OR(G26="✅ Đúng", I26="✅ Đúng", K26="✅ Đúng"), "✨ Xuất sắc! Bạn đã làm đúng.", IF(NOT(ISBLANK(J26)), "💡 Gợi ý Tầng 3 (Chốt phương pháp): " & "Chọn từ nối thể hiện chính xác mối quan hệ trình tự/kết quả được thiết lập.", IF(NOT(ISBLANK(H26)), "💡 Gợi ý Tầng 2 (Manh mối cấu trúc & Loại trừ): " & "Xác định xem câu sau đưa ra kết quả, sự đối lập, hay bước tiếp theo trong trình tự.", "💡 Gợi ý Tầng 1 (Định hướng bối cảnh): " & "Phân tích mối quan hệ logic giữa hai câu văn đứng trước và sau từ nối.")))) | P26: =IF(OR(G26="✅ Đúng", I26="✅ Đúng", K26="✅ Đúng"), "Từ nối chỉ thứ tự các bước trong quy trình: Next.", "🔒 Trả lời đúng để mở khóa Strategic Tip!")
A27: Q23 | B27: Transitions (Elaboration & Specifics) | C27: Scientists studying forest restoration have discovered that trees depend on complex partnerships with microscopic organisms for survival. The researchers found that special fungi called endophytes live inside tree leaves and serve as a defense mechanism. ______ these endophytes help by fighting off diseases and boosting the tree’s immune system. | D27: Which choice completes the text with the most logical transition? | E27: A. Lựa chọn A B. Lựa chọn B C. Lựa chọn C D. Lựa chọn D | G27: =IF(ISBLANK(F27), "⏳ Chờ đáp án", IF(UPPER(TRIM(F27))="D", "✅ Đúng", "❌ Sai")) | I27: =IF(ISBLANK(H27), "", IF(UPPER(TRIM(H27))="D", "✅ Đúng", "❌ Sai")) | K27: =IF(ISBLANK(J27), "", IF(UPPER(TRIM(J27))="D", "✅ Đúng", "❌ Sai")) | L27: =COUNTIF(G27, "❌ Sai") + COUNTIF(I27, "❌ Sai") + COUNTIF(K27, "❌ Sai") | M27: =IF(ISBLANK(F27), "⏳ Chờ làm", IF(G27="✅ Đúng", "✅ Đúng ngay L1", IF(I27="✅ Đúng", "✅ Đúng ở L2", IF(K27="✅ Đúng", "✅ Đúng ở L3", "❌ Chưa đúng sau 3 lần")))) | N27: =IF(G27="✅ Đúng", 1, IF(I27="✅ Đúng", 0.667, IF(K27="✅ Đúng", 0.333, 0))) | O27: =IF(ISBLANK(F27), "💡 Nhập đáp án vào Lần thử 1", IF(OR(G27="✅ Đúng", I27="✅ Đúng", K27="✅ Đúng"), "✨ Xuất sắc! Bạn đã làm đúng.", IF(NOT(ISBLANK(J27)), "💡 Gợi ý Tầng 3 (Chốt phương pháp): " & "Chọn từ nối mang nghĩa cụ thể hóa, minh họa hoặc diễn giải thêm.", IF(NOT(ISBLANK(H27)), "💡 Gợi ý Tầng 2 (Manh mối cấu trúc & Loại trừ): " & "Câu sau đưa ra thông tin chi tiết hoặc ví dụ cụ thể để làm rõ hơn cho nhận định trước.", "💡 Gợi ý Tầng 1 (Định hướng bối cảnh): " & "Xác định vai trò của câu sau đối với ý tưởng tổng quát đã phát biểu ở câu trước.")))) | P27: =IF(OR(G27="✅ Đúng", I27="✅ Đúng", K27="✅ Đúng"), "Specifically = đi vào chi tiết minh họa cụ thể.", "🔒 Trả lời đúng để mở khóa Strategic Tip!")
A28: Q24 | B28: Rhetorical Synthesis / Student Notes | C28: While researching a topic, a student has taken the following notes: • Pistol shrimp are small marine crustaceans that hunt using a specialized oversized claw. • When the claw snaps shut rapidly, it pushes water through a narrow groove at extreme speeds. • This high-speed water jet creates a bubble that pops forcefully near the shrimp’s prey. • The popping bubble generates shock waves powerful enough to stun small fish. | D28: The student wants to introduce pistol shrimp to an audience unfamiliar with these crustaceans. Which choice most effectively uses relevant information from the notes to accomplish this goal? | E28: A. Lựa chọn A B. Lựa chọn B C. Lựa chọn C D. Lựa chọn D | G28: =IF(ISBLANK(F28), "⏳ Chờ đáp án", IF(UPPER(TRIM(F28))="B", "✅ Đúng", "❌ Sai")) | I28: =IF(ISBLANK(H28), "", IF(UPPER(TRIM(H28))="B", "✅ Đúng", "❌ Sai")) | K28: =IF(ISBLANK(J28), "", IF(UPPER(TRIM(J28))="B", "✅ Đúng", "❌ Sai")) | L28: =COUNTIF(G28, "❌ Sai") + COUNTIF(I28, "❌ Sai") + COUNTIF(K28, "❌ Sai") | M28: =IF(ISBLANK(F28), "⏳ Chờ làm", IF(G28="✅ Đúng", "✅ Đúng ngay L1", IF(I28="✅ Đúng", "✅ Đúng ở L2", IF(K28="✅ Đúng", "✅ Đúng ở L3", "❌ Chưa đúng sau 3 lần")))) | N28: =IF(G28="✅ Đúng", 1, IF(I28="✅ Đúng", 0.667, IF(K28="✅ Đúng", 0.333, 0))) | O28: =IF(ISBLANK(F28), "💡 Nhập đáp án vào Lần thử 1", IF(OR(G28="✅ Đúng", I28="✅ Đúng", K28="✅ Đúng"), "✨ Xuất sắc! Bạn đã làm đúng.", IF(NOT(ISBLANK(J28)), "💡 Gợi ý Tầng 3 (Chốt phương pháp): " & "Chọn câu tổng hợp trực tiếp đáp ứng đúng mục tiêu đề bài mà không thừa thông tin ngoài.", IF(NOT(ISBLANK(H28)), "💡 Gợi ý Tầng 2 (Manh mối cấu trúc & Loại trừ): " & "So sánh các ghi chú với mục tiêu được chỉ định trong yêu cầu.", "💡 Gợi ý Tầng 1 (Định hướng bối cảnh): " & "Đọc kỹ yêu cầu đề bài (Goal) để biết thông tin nào cần được ưu tiên làm nổi bật.")))) | P28: =IF(OR(G28="✅ Đúng", I28="✅ Đúng", K28="✅ Đúng"), "Giới thiệu đối tượng mới = Nêu tên đối tượng + Định nghĩa/Đặc điểm nhận diện chính.", "🔒 Trả lời đúng để mở khóa Strategic Tip!")
A29: Q25 | B29: Rhetorical Synthesis / Student Notes | C29: While researching a topic, a student has taken the following notes: • Elizabeth Catlett (1915–2012) was a celebrated African American artist. • She is best known for creating sculptures and prints that explore the Black experience. • Standing Mother and Child is a 1980 sculpture by Catlett. • New Generation is a 1992 print by Catlett. | D29: The student wants to provide an example of one of Catlett’s sculptures. Which choice most effectively uses relevant information from the notes to accomplish this goal? | E29: A. Lựa chọn A B. Lựa chọn B C. Lựa chọn C D. Lựa chọn D | G29: =IF(ISBLANK(F29), "⏳ Chờ đáp án", IF(UPPER(TRIM(F29))="B", "✅ Đúng", "❌ Sai")) | I29: =IF(ISBLANK(H29), "", IF(UPPER(TRIM(H29))="B", "✅ Đúng", "❌ Sai")) | K29: =IF(ISBLANK(J29), "", IF(UPPER(TRIM(J29))="B", "✅ Đúng", "❌ Sai")) | L29: =COUNTIF(G29, "❌ Sai") + COUNTIF(I29, "❌ Sai") + COUNTIF(K29, "❌ Sai") | M29: =IF(ISBLANK(F29), "⏳ Chờ làm", IF(G29="✅ Đúng", "✅ Đúng ngay L1", IF(I29="✅ Đúng", "✅ Đúng ở L2", IF(K29="✅ Đúng", "✅ Đúng ở L3", "❌ Chưa đúng sau 3 lần")))) | N29: =IF(G29="✅ Đúng", 1, IF(I29="✅ Đúng", 0.667, IF(K29="✅ Đúng", 0.333, 0))) | O29: =IF(ISBLANK(F29), "💡 Nhập đáp án vào Lần thử 1", IF(OR(G29="✅ Đúng", I29="✅ Đúng", K29="✅ Đúng"), "✨ Xuất sắc! Bạn đã làm đúng.", IF(NOT(ISBLANK(J29)), "💡 Gợi ý Tầng 3 (Chốt phương pháp): " & "Chọn câu diễn đạt ngắn gọn, tập trung vào điểm nhấn được đề bài yêu cầu.", IF(NOT(ISBLANK(H29)), "💡 Gợi ý Tầng 2 (Manh mối cấu trúc & Loại trừ): " & "Lọc các ghi chú liên quan đến đối tượng hoặc sự kiện được chỉ định.", "💡 Gợi ý Tầng 1 (Định hướng bối cảnh): " & "Xác định khía cạnh cụ thể mà đề bài yêu cầu người học phải nhấn mạnh từ ghi chú.")))) | P29: =IF(OR(G29="✅ Đúng", I29="✅ Đúng", K29="✅ Đúng"), "Đọc kĩ yêu cầu cụ thể của đề bài: 'example of one of Catlett's sculptures'.", "🔒 Trả lời đúng để mở khóa Strategic Tip!")
A30: Q26 | B30: Rhetorical Synthesis / Student Notes | C30: While researching a topic, a student has taken the following notes: • Chapantongo is a municipality in the state of Hidalgo, Mexico. • Municipalities are governmental regions responsible for providing many public services to their residents. • One service they provide is traffic control. • Chapantongo’s population was 12,967 in 2020. • Its population was 12,271 in 2010. • Hidalgo is divided into 84 municipalities. | D30: The student wants to emphasize the 2020 population of Chapantongo. Which choice most effectively uses relevant information from the notes to accomplish this goal? | E30: A. Lựa chọn A B. Lựa chọn B C. Lựa chọn C D. Lựa chọn D | G30: =IF(ISBLANK(F30), "⏳ Chờ đáp án", IF(UPPER(TRIM(F30))="B", "✅ Đúng", "❌ Sai")) | I30: =IF(ISBLANK(H30), "", IF(UPPER(TRIM(H30))="B", "✅ Đúng", "❌ Sai")) | K30: =IF(ISBLANK(J30), "", IF(UPPER(TRIM(J30))="B", "✅ Đúng", "❌ Sai")) | L30: =COUNTIF(G30, "❌ Sai") + COUNTIF(I30, "❌ Sai") + COUNTIF(K30, "❌ Sai") | M30: =IF(ISBLANK(F30), "⏳ Chờ làm", IF(G30="✅ Đúng", "✅ Đúng ngay L1", IF(I30="✅ Đúng", "✅ Đúng ở L2", IF(K30="✅ Đúng", "✅ Đúng ở L3", "❌ Chưa đúng sau 3 lần")))) | N30: =IF(G30="✅ Đúng", 1, IF(I30="✅ Đúng", 0.667, IF(K30="✅ Đúng", 0.333, 0))) | O30: =IF(ISBLANK(F30), "💡 Nhập đáp án vào Lần thử 1", IF(OR(G30="✅ Đúng", I30="✅ Đúng", K30="✅ Đúng"), "✨ Xuất sắc! Bạn đã làm đúng.", IF(NOT(ISBLANK(J30)), "💡 Gợi ý Tầng 3 (Chốt phương pháp): " & "Chọn đáp án có cấu trúc song song, truyền tải chính xác mối quan hệ giữa các dữ kiện.", IF(NOT(ISBLANK(H30)), "💡 Gợi ý Tầng 2 (Manh mối cấu trúc & Loại trừ): " & "Đối chiếu thông tin trong các ghi chú để tìm câu kết hợp đầy đủ hai vế cần so sánh.", "💡 Gợi ý Tầng 1 (Định hướng bối cảnh): " & "Xem xét mục tiêu bài viết (ví dụ: so sánh hai nghiên cứu hay giới thiệu một phát minh).")))) | P30: =IF(OR(G30="✅ Đúng", I30="✅ Đúng", K30="✅ Đúng"), "Đáp án phải chứa thông tin được yêu cầu làm trọng tâm: 2020 population = 12,967.", "🔒 Trả lời đúng để mở khóa Strategic Tip!")
A31: Q27 | B31: Rhetorical Synthesis / Student Notes | C31: While researching a topic, a student has taken the following notes: • The Future of Nostalgia is a scholarly book by literary theorist Svetlana Boym. • The book explores the concept of nostalgia from various angles. • Chapter 8 explores nostalgia and Europe’s largest shopping mall. • Chapter 17 discusses various skeptics’ takes on the concept of nostalgia. • In chapter 17, Boym writes, “The poethics of nostalgia combines estrangement and human solidarity, affect and reflection.” | D31: The student wants to explain what Svetlana Boym writes about in chapter 8. Which choice most effectively uses relevant information from the notes to accomplish this goal? | E31: A. Lựa chọn A B. Lựa chọn B C. Lựa chọn C D. Lựa chọn D | G31: =IF(ISBLANK(F31), "⏳ Chờ đáp án", IF(UPPER(TRIM(F31))="C", "✅ Đúng", "❌ Sai")) | I31: =IF(ISBLANK(H31), "", IF(UPPER(TRIM(H31))="C", "✅ Đúng", "❌ Sai")) | K31: =IF(ISBLANK(J31), "", IF(UPPER(TRIM(J31))="C", "✅ Đúng", "❌ Sai")) | L31: =COUNTIF(G31, "❌ Sai") + COUNTIF(I31, "❌ Sai") + COUNTIF(K31, "❌ Sai") | M31: =IF(ISBLANK(F31), "⏳ Chờ làm", IF(G31="✅ Đúng", "✅ Đúng ngay L1", IF(I31="✅ Đúng", "✅ Đúng ở L2", IF(K31="✅ Đúng", "✅ Đúng ở L3", "❌ Chưa đúng sau 3 lần")))) | N31: =IF(G31="✅ Đúng", 1, IF(I31="✅ Đúng", 0.667, IF(K31="✅ Đúng", 0.333, 0))) | O31: =IF(ISBLANK(F31), "💡 Nhập đáp án vào Lần thử 1", IF(OR(G31="✅ Đúng", I31="✅ Đúng", K31="✅ Đúng"), "✨ Xuất sắc! Bạn đã làm đúng.", IF(NOT(ISBLANK(J31)), "💡 Gợi ý Tầng 3 (Chốt phương pháp): " & "Chọn câu liên kết các ghi chú một cách mượt mà và đúng trọng tâm đề bài.", IF(NOT(ISBLANK(H31)), "💡 Gợi ý Tầng 2 (Manh mối cấu trúc & Loại trừ): " & "Lựa chọn thông tin trong danh sách ghi chú trực tiếp phục vụ cho mục đích đó.", "💡 Gợi ý Tầng 1 (Định hướng bối cảnh): " & "Đọc yêu cầu để xác định đối tượng khán giả hoặc mục đích của câu văn cần viết.")))) | P31: =IF(OR(G31="✅ Đúng", I31="✅ Đúng", K31="✅ Đúng"), "Chỉ chọn phương án trả lời đúng mục tiêu 'explain what Boym writes in chapter 8'.", "🔒 Trả lời đúng để mở khóa Strategic Tip!")

Sheet RW_Module2
A1: Digital SAT Practice Test - October 2026: Reading & Writing Module 2
A2: Chiến thuật: Tự thử sức ở Lần 1 (Cột F) -> Nhận phản hồi tự động & Gợi ý định hướng logic mà không làm lộ đáp án.
A4: Q# | B4: Topic / Skill Focus | C4: Passage & Context | D4: Question Prompt / Calculator | E4: Options / Choices (No Answer) | F4: Lần thử 1 | G4: Kết quả L1 | H4: Lần thử 2 | I4: Kết quả L2 | J4: Lần thử 3 | K4: Kết quả L3 | L4: Tổng số cột Sai | M4: Trạng thái Hoàn thành | N4: Hiệu suất (%) | O4: Hint / Gợi ý Đa tầng (Không đáp án) | P4: Strategic Tip / Formula
